{
 "cells": [
  {
   "cell_type": "code",
   "execution_count": 13,
   "id": "e188d71f",
   "metadata": {},
   "outputs": [
    {
     "name": "stderr",
     "output_type": "stream",
     "text": [
      "WARNING: Retrying (Retry(total=4, connect=None, read=None, redirect=None, status=None)) after connection broken by 'ReadTimeoutError(\"HTTPSConnectionPool(host='developer.download.nvidia.com', port=443): Read timed out. (read timeout=15)\")': /compute/redist/tensorflow-intel/\n",
      "ERROR: Exception:\n",
      "Traceback (most recent call last):\n",
      "  File \"C:\\Users\\HP\\anaconda3\\lib\\site-packages\\pip\\_vendor\\urllib3\\response.py\", line 438, in _error_catcher\n",
      "    yield\n",
      "  File \"C:\\Users\\HP\\anaconda3\\lib\\site-packages\\pip\\_vendor\\urllib3\\response.py\", line 519, in read\n",
      "    data = self._fp.read(amt) if not fp_closed else b\"\"\n",
      "  File \"C:\\Users\\HP\\anaconda3\\lib\\http\\client.py\", line 463, in read\n",
      "    n = self.readinto(b)\n",
      "  File \"C:\\Users\\HP\\anaconda3\\lib\\http\\client.py\", line 507, in readinto\n",
      "    n = self.fp.readinto(b)\n",
      "  File \"C:\\Users\\HP\\anaconda3\\lib\\socket.py\", line 704, in readinto\n",
      "    return self._sock.recv_into(b)\n",
      "  File \"C:\\Users\\HP\\anaconda3\\lib\\ssl.py\", line 1241, in recv_into\n",
      "    return self.read(nbytes, buffer)\n",
      "  File \"C:\\Users\\HP\\anaconda3\\lib\\ssl.py\", line 1099, in read\n",
      "    return self._sslobj.read(len, buffer)\n",
      "socket.timeout: The read operation timed out\n",
      "\n",
      "During handling of the above exception, another exception occurred:\n",
      "\n",
      "Traceback (most recent call last):\n",
      "  File \"C:\\Users\\HP\\anaconda3\\lib\\site-packages\\pip\\_internal\\cli\\base_command.py\", line 173, in _main\n",
      "    status = self.run(options, args)\n",
      "  File \"C:\\Users\\HP\\anaconda3\\lib\\site-packages\\pip\\_internal\\cli\\req_command.py\", line 203, in wrapper\n",
      "    return func(self, options, args)\n",
      "  File \"C:\\Users\\HP\\anaconda3\\lib\\site-packages\\pip\\_internal\\commands\\install.py\", line 315, in run\n",
      "    requirement_set = resolver.resolve(\n",
      "  File \"C:\\Users\\HP\\anaconda3\\lib\\site-packages\\pip\\_internal\\resolution\\resolvelib\\resolver.py\", line 94, in resolve\n",
      "    result = self._result = resolver.resolve(\n",
      "  File \"C:\\Users\\HP\\anaconda3\\lib\\site-packages\\pip\\_vendor\\resolvelib\\resolvers.py\", line 472, in resolve\n",
      "    state = resolution.resolve(requirements, max_rounds=max_rounds)\n",
      "  File \"C:\\Users\\HP\\anaconda3\\lib\\site-packages\\pip\\_vendor\\resolvelib\\resolvers.py\", line 366, in resolve\n",
      "    failure_causes = self._attempt_to_pin_criterion(name)\n",
      "  File \"C:\\Users\\HP\\anaconda3\\lib\\site-packages\\pip\\_vendor\\resolvelib\\resolvers.py\", line 212, in _attempt_to_pin_criterion\n",
      "    criteria = self._get_updated_criteria(candidate)\n",
      "  File \"C:\\Users\\HP\\anaconda3\\lib\\site-packages\\pip\\_vendor\\resolvelib\\resolvers.py\", line 203, in _get_updated_criteria\n",
      "    self._add_to_criteria(criteria, requirement, parent=candidate)\n",
      "  File \"C:\\Users\\HP\\anaconda3\\lib\\site-packages\\pip\\_vendor\\resolvelib\\resolvers.py\", line 172, in _add_to_criteria\n",
      "    if not criterion.candidates:\n",
      "  File \"C:\\Users\\HP\\anaconda3\\lib\\site-packages\\pip\\_vendor\\resolvelib\\structs.py\", line 151, in __bool__\n",
      "    return bool(self._sequence)\n",
      "  File \"C:\\Users\\HP\\anaconda3\\lib\\site-packages\\pip\\_internal\\resolution\\resolvelib\\found_candidates.py\", line 140, in __bool__\n",
      "    return any(self)\n",
      "  File \"C:\\Users\\HP\\anaconda3\\lib\\site-packages\\pip\\_internal\\resolution\\resolvelib\\found_candidates.py\", line 128, in <genexpr>\n",
      "    return (c for c in iterator if id(c) not in self._incompatible_ids)\n",
      "  File \"C:\\Users\\HP\\anaconda3\\lib\\site-packages\\pip\\_internal\\resolution\\resolvelib\\found_candidates.py\", line 32, in _iter_built\n",
      "    candidate = func()\n",
      "  File \"C:\\Users\\HP\\anaconda3\\lib\\site-packages\\pip\\_internal\\resolution\\resolvelib\\factory.py\", line 204, in _make_candidate_from_link\n",
      "    self._link_candidate_cache[link] = LinkCandidate(\n",
      "  File \"C:\\Users\\HP\\anaconda3\\lib\\site-packages\\pip\\_internal\\resolution\\resolvelib\\candidates.py\", line 295, in __init__\n",
      "    super().__init__(\n",
      "  File \"C:\\Users\\HP\\anaconda3\\lib\\site-packages\\pip\\_internal\\resolution\\resolvelib\\candidates.py\", line 156, in __init__\n",
      "    self.dist = self._prepare()\n",
      "  File \"C:\\Users\\HP\\anaconda3\\lib\\site-packages\\pip\\_internal\\resolution\\resolvelib\\candidates.py\", line 227, in _prepare\n",
      "    dist = self._prepare_distribution()\n",
      "  File \"C:\\Users\\HP\\anaconda3\\lib\\site-packages\\pip\\_internal\\resolution\\resolvelib\\candidates.py\", line 305, in _prepare_distribution\n",
      "    return self._factory.preparer.prepare_linked_requirement(\n",
      "  File \"C:\\Users\\HP\\anaconda3\\lib\\site-packages\\pip\\_internal\\operations\\prepare.py\", line 508, in prepare_linked_requirement\n",
      "    return self._prepare_linked_requirement(req, parallel_builds)\n",
      "  File \"C:\\Users\\HP\\anaconda3\\lib\\site-packages\\pip\\_internal\\operations\\prepare.py\", line 550, in _prepare_linked_requirement\n",
      "    local_file = unpack_url(\n",
      "  File \"C:\\Users\\HP\\anaconda3\\lib\\site-packages\\pip\\_internal\\operations\\prepare.py\", line 239, in unpack_url\n",
      "    file = get_http_url(\n",
      "  File \"C:\\Users\\HP\\anaconda3\\lib\\site-packages\\pip\\_internal\\operations\\prepare.py\", line 102, in get_http_url\n",
      "    from_path, content_type = download(link, temp_dir.path)\n",
      "  File \"C:\\Users\\HP\\anaconda3\\lib\\site-packages\\pip\\_internal\\network\\download.py\", line 145, in __call__\n",
      "    for chunk in chunks:\n",
      "  File \"C:\\Users\\HP\\anaconda3\\lib\\site-packages\\pip\\_internal\\cli\\progress_bars.py\", line 144, in iter\n",
      "    for x in it:\n",
      "  File \"C:\\Users\\HP\\anaconda3\\lib\\site-packages\\pip\\_internal\\network\\utils.py\", line 63, in response_chunks\n",
      "    for chunk in response.raw.stream(\n",
      "  File \"C:\\Users\\HP\\anaconda3\\lib\\site-packages\\pip\\_vendor\\urllib3\\response.py\", line 576, in stream\n",
      "    data = self.read(amt=amt, decode_content=decode_content)\n",
      "  File \"C:\\Users\\HP\\anaconda3\\lib\\site-packages\\pip\\_vendor\\urllib3\\response.py\", line 541, in read\n",
      "    raise IncompleteRead(self._fp_bytes_read, self.length_remaining)\n",
      "  File \"C:\\Users\\HP\\anaconda3\\lib\\contextlib.py\", line 137, in __exit__\n",
      "    self.gen.throw(typ, value, traceback)\n",
      "  File \"C:\\Users\\HP\\anaconda3\\lib\\site-packages\\pip\\_vendor\\urllib3\\response.py\", line 443, in _error_catcher\n",
      "    raise ReadTimeoutError(self._pool, None, \"Read timed out.\")\n",
      "pip._vendor.urllib3.exceptions.ReadTimeoutError: HTTPSConnectionPool(host='files.pythonhosted.org', port=443): Read timed out.\n"
     ]
    },
    {
     "name": "stdout",
     "output_type": "stream",
     "text": [
      "Looking in indexes: https://pypi.org/simple, https://pypi.ngc.nvidia.com\n",
      "Collecting tensorflow\n",
      "  Downloading tensorflow-2.11.0-cp39-cp39-win_amd64.whl (1.9 kB)\n",
      "Collecting tensorflow-intel==2.11.0\n",
      "  Downloading tensorflow_intel-2.11.0-cp39-cp39-win_amd64.whl (266.3 MB)\n",
      "Looking in indexes: https://pypi.org/simple, https://pypi.ngc.nvidia.com\n",
      "Collecting tensorflow\n",
      "  Downloading tensorflow-2.11.0-cp39-cp39-win_amd64.whl (1.9 kB)\n",
      "Collecting tensorflow-intel==2.11.0\n",
      "  Downloading tensorflow_intel-2.11.0-cp39-cp39-win_amd64.whl (266.3 MB)\n",
      "Note: you may need to restart the kernel to use updated packages.\n"
     ]
    },
    {
     "name": "stderr",
     "output_type": "stream",
     "text": [
      "ERROR: Exception:\n",
      "Traceback (most recent call last):\n",
      "  File \"C:\\Users\\HP\\anaconda3\\lib\\site-packages\\pip\\_vendor\\urllib3\\response.py\", line 438, in _error_catcher\n",
      "    yield\n",
      "  File \"C:\\Users\\HP\\anaconda3\\lib\\site-packages\\pip\\_vendor\\urllib3\\response.py\", line 519, in read\n",
      "    data = self._fp.read(amt) if not fp_closed else b\"\"\n",
      "  File \"C:\\Users\\HP\\anaconda3\\lib\\http\\client.py\", line 463, in read\n",
      "    n = self.readinto(b)\n",
      "  File \"C:\\Users\\HP\\anaconda3\\lib\\http\\client.py\", line 507, in readinto\n",
      "    n = self.fp.readinto(b)\n",
      "  File \"C:\\Users\\HP\\anaconda3\\lib\\socket.py\", line 704, in readinto\n",
      "    return self._sock.recv_into(b)\n",
      "  File \"C:\\Users\\HP\\anaconda3\\lib\\ssl.py\", line 1241, in recv_into\n",
      "    return self.read(nbytes, buffer)\n",
      "  File \"C:\\Users\\HP\\anaconda3\\lib\\ssl.py\", line 1099, in read\n",
      "    return self._sslobj.read(len, buffer)\n",
      "socket.timeout: The read operation timed out\n",
      "\n",
      "During handling of the above exception, another exception occurred:\n",
      "\n",
      "Traceback (most recent call last):\n",
      "  File \"C:\\Users\\HP\\anaconda3\\lib\\site-packages\\pip\\_internal\\cli\\base_command.py\", line 173, in _main\n",
      "    status = self.run(options, args)\n",
      "  File \"C:\\Users\\HP\\anaconda3\\lib\\site-packages\\pip\\_internal\\cli\\req_command.py\", line 203, in wrapper\n",
      "    return func(self, options, args)\n",
      "  File \"C:\\Users\\HP\\anaconda3\\lib\\site-packages\\pip\\_internal\\commands\\install.py\", line 315, in run\n",
      "    requirement_set = resolver.resolve(\n",
      "  File \"C:\\Users\\HP\\anaconda3\\lib\\site-packages\\pip\\_internal\\resolution\\resolvelib\\resolver.py\", line 94, in resolve\n",
      "    result = self._result = resolver.resolve(\n",
      "  File \"C:\\Users\\HP\\anaconda3\\lib\\site-packages\\pip\\_vendor\\resolvelib\\resolvers.py\", line 472, in resolve\n",
      "    state = resolution.resolve(requirements, max_rounds=max_rounds)\n",
      "  File \"C:\\Users\\HP\\anaconda3\\lib\\site-packages\\pip\\_vendor\\resolvelib\\resolvers.py\", line 366, in resolve\n",
      "    failure_causes = self._attempt_to_pin_criterion(name)\n",
      "  File \"C:\\Users\\HP\\anaconda3\\lib\\site-packages\\pip\\_vendor\\resolvelib\\resolvers.py\", line 212, in _attempt_to_pin_criterion\n",
      "    criteria = self._get_updated_criteria(candidate)\n",
      "  File \"C:\\Users\\HP\\anaconda3\\lib\\site-packages\\pip\\_vendor\\resolvelib\\resolvers.py\", line 203, in _get_updated_criteria\n",
      "    self._add_to_criteria(criteria, requirement, parent=candidate)\n",
      "  File \"C:\\Users\\HP\\anaconda3\\lib\\site-packages\\pip\\_vendor\\resolvelib\\resolvers.py\", line 172, in _add_to_criteria\n",
      "    if not criterion.candidates:\n",
      "  File \"C:\\Users\\HP\\anaconda3\\lib\\site-packages\\pip\\_vendor\\resolvelib\\structs.py\", line 151, in __bool__\n",
      "    return bool(self._sequence)\n",
      "  File \"C:\\Users\\HP\\anaconda3\\lib\\site-packages\\pip\\_internal\\resolution\\resolvelib\\found_candidates.py\", line 140, in __bool__\n",
      "    return any(self)\n",
      "  File \"C:\\Users\\HP\\anaconda3\\lib\\site-packages\\pip\\_internal\\resolution\\resolvelib\\found_candidates.py\", line 128, in <genexpr>\n",
      "    return (c for c in iterator if id(c) not in self._incompatible_ids)\n",
      "  File \"C:\\Users\\HP\\anaconda3\\lib\\site-packages\\pip\\_internal\\resolution\\resolvelib\\found_candidates.py\", line 32, in _iter_built\n",
      "    candidate = func()\n",
      "  File \"C:\\Users\\HP\\anaconda3\\lib\\site-packages\\pip\\_internal\\resolution\\resolvelib\\factory.py\", line 204, in _make_candidate_from_link\n",
      "    self._link_candidate_cache[link] = LinkCandidate(\n",
      "  File \"C:\\Users\\HP\\anaconda3\\lib\\site-packages\\pip\\_internal\\resolution\\resolvelib\\candidates.py\", line 295, in __init__\n",
      "    super().__init__(\n",
      "  File \"C:\\Users\\HP\\anaconda3\\lib\\site-packages\\pip\\_internal\\resolution\\resolvelib\\candidates.py\", line 156, in __init__\n",
      "    self.dist = self._prepare()\n",
      "  File \"C:\\Users\\HP\\anaconda3\\lib\\site-packages\\pip\\_internal\\resolution\\resolvelib\\candidates.py\", line 227, in _prepare\n",
      "    dist = self._prepare_distribution()\n",
      "  File \"C:\\Users\\HP\\anaconda3\\lib\\site-packages\\pip\\_internal\\resolution\\resolvelib\\candidates.py\", line 305, in _prepare_distribution\n",
      "    return self._factory.preparer.prepare_linked_requirement(\n",
      "  File \"C:\\Users\\HP\\anaconda3\\lib\\site-packages\\pip\\_internal\\operations\\prepare.py\", line 508, in prepare_linked_requirement\n",
      "    return self._prepare_linked_requirement(req, parallel_builds)\n",
      "  File \"C:\\Users\\HP\\anaconda3\\lib\\site-packages\\pip\\_internal\\operations\\prepare.py\", line 550, in _prepare_linked_requirement\n",
      "    local_file = unpack_url(\n",
      "  File \"C:\\Users\\HP\\anaconda3\\lib\\site-packages\\pip\\_internal\\operations\\prepare.py\", line 239, in unpack_url\n",
      "    file = get_http_url(\n",
      "  File \"C:\\Users\\HP\\anaconda3\\lib\\site-packages\\pip\\_internal\\operations\\prepare.py\", line 102, in get_http_url\n",
      "    from_path, content_type = download(link, temp_dir.path)\n",
      "  File \"C:\\Users\\HP\\anaconda3\\lib\\site-packages\\pip\\_internal\\network\\download.py\", line 145, in __call__\n",
      "    for chunk in chunks:\n",
      "  File \"C:\\Users\\HP\\anaconda3\\lib\\site-packages\\pip\\_internal\\cli\\progress_bars.py\", line 144, in iter\n",
      "    for x in it:\n",
      "  File \"C:\\Users\\HP\\anaconda3\\lib\\site-packages\\pip\\_internal\\network\\utils.py\", line 63, in response_chunks\n",
      "    for chunk in response.raw.stream(\n",
      "  File \"C:\\Users\\HP\\anaconda3\\lib\\site-packages\\pip\\_vendor\\urllib3\\response.py\", line 576, in stream\n",
      "    data = self.read(amt=amt, decode_content=decode_content)\n",
      "  File \"C:\\Users\\HP\\anaconda3\\lib\\site-packages\\pip\\_vendor\\urllib3\\response.py\", line 541, in read\n",
      "    raise IncompleteRead(self._fp_bytes_read, self.length_remaining)\n",
      "  File \"C:\\Users\\HP\\anaconda3\\lib\\contextlib.py\", line 137, in __exit__\n",
      "    self.gen.throw(typ, value, traceback)\n",
      "  File \"C:\\Users\\HP\\anaconda3\\lib\\site-packages\\pip\\_vendor\\urllib3\\response.py\", line 443, in _error_catcher\n",
      "    raise ReadTimeoutError(self._pool, None, \"Read timed out.\")\n",
      "pip._vendor.urllib3.exceptions.ReadTimeoutError: HTTPSConnectionPool(host='files.pythonhosted.org', port=443): Read timed out.\n"
     ]
    }
   ],
   "source": [
    "pip install tensorflow"
   ]
  },
  {
   "cell_type": "code",
   "execution_count": 10,
   "id": "95e5e26f",
   "metadata": {},
   "outputs": [
    {
     "ename": "ModuleNotFoundError",
     "evalue": "No module named 'tensorflow'",
     "output_type": "error",
     "traceback": [
      "\u001b[1;31m---------------------------------------------------------------------------\u001b[0m",
      "\u001b[1;31mModuleNotFoundError\u001b[0m                       Traceback (most recent call last)",
      "Input \u001b[1;32mIn [10]\u001b[0m, in \u001b[0;36m<cell line: 1>\u001b[1;34m()\u001b[0m\n\u001b[1;32m----> 1\u001b[0m \u001b[38;5;28;01mfrom\u001b[39;00m \u001b[38;5;21;01mkeras\u001b[39;00m\u001b[38;5;21;01m.\u001b[39;00m\u001b[38;5;21;01mmodels\u001b[39;00m \u001b[38;5;28;01mimport\u001b[39;00m Model\n\u001b[0;32m      2\u001b[0m \u001b[38;5;28;01mfrom\u001b[39;00m \u001b[38;5;21;01mkeras\u001b[39;00m\u001b[38;5;21;01m.\u001b[39;00m\u001b[38;5;21;01mlayers\u001b[39;00m \u001b[38;5;28;01mimport\u001b[39;00m Flatten,Dense\n\u001b[0;32m      3\u001b[0m \u001b[38;5;28;01mfrom\u001b[39;00m \u001b[38;5;21;01mkeras\u001b[39;00m\u001b[38;5;21;01m.\u001b[39;00m\u001b[38;5;21;01mapplications\u001b[39;00m\u001b[38;5;21;01m.\u001b[39;00m\u001b[38;5;21;01mvgg16\u001b[39;00m \u001b[38;5;28;01mimport\u001b[39;00m VGG16\n",
      "File \u001b[1;32m~\\anaconda3\\lib\\site-packages\\keras\\__init__.py:21\u001b[0m, in \u001b[0;36m<module>\u001b[1;34m\u001b[0m\n\u001b[0;32m     15\u001b[0m \u001b[38;5;124;03m\"\"\"Implementation of the Keras API, the high-level API of TensorFlow.\u001b[39;00m\n\u001b[0;32m     16\u001b[0m \n\u001b[0;32m     17\u001b[0m \u001b[38;5;124;03mDetailed documentation and user guides are available at\u001b[39;00m\n\u001b[0;32m     18\u001b[0m \u001b[38;5;124;03m[keras.io](https://keras.io).\u001b[39;00m\n\u001b[0;32m     19\u001b[0m \u001b[38;5;124;03m\"\"\"\u001b[39;00m\n\u001b[0;32m     20\u001b[0m \u001b[38;5;28;01mfrom\u001b[39;00m \u001b[38;5;21;01mkeras\u001b[39;00m \u001b[38;5;28;01mimport\u001b[39;00m distribute\n\u001b[1;32m---> 21\u001b[0m \u001b[38;5;28;01mfrom\u001b[39;00m \u001b[38;5;21;01mkeras\u001b[39;00m \u001b[38;5;28;01mimport\u001b[39;00m models\n\u001b[0;32m     22\u001b[0m \u001b[38;5;28;01mfrom\u001b[39;00m \u001b[38;5;21;01mkeras\u001b[39;00m\u001b[38;5;21;01m.\u001b[39;00m\u001b[38;5;21;01mengine\u001b[39;00m\u001b[38;5;21;01m.\u001b[39;00m\u001b[38;5;21;01minput_layer\u001b[39;00m \u001b[38;5;28;01mimport\u001b[39;00m Input\n\u001b[0;32m     23\u001b[0m \u001b[38;5;28;01mfrom\u001b[39;00m \u001b[38;5;21;01mkeras\u001b[39;00m\u001b[38;5;21;01m.\u001b[39;00m\u001b[38;5;21;01mengine\u001b[39;00m\u001b[38;5;21;01m.\u001b[39;00m\u001b[38;5;21;01msequential\u001b[39;00m \u001b[38;5;28;01mimport\u001b[39;00m Sequential\n",
      "File \u001b[1;32m~\\anaconda3\\lib\\site-packages\\keras\\models\\__init__.py:18\u001b[0m, in \u001b[0;36m<module>\u001b[1;34m\u001b[0m\n\u001b[0;32m      1\u001b[0m \u001b[38;5;66;03m# Copyright 2022 The TensorFlow Authors. All Rights Reserved.\u001b[39;00m\n\u001b[0;32m      2\u001b[0m \u001b[38;5;66;03m#\u001b[39;00m\n\u001b[0;32m      3\u001b[0m \u001b[38;5;66;03m# Licensed under the Apache License, Version 2.0 (the \"License\");\u001b[39;00m\n\u001b[1;32m   (...)\u001b[0m\n\u001b[0;32m     13\u001b[0m \u001b[38;5;66;03m# limitations under the License.\u001b[39;00m\n\u001b[0;32m     14\u001b[0m \u001b[38;5;66;03m# ==============================================================================\u001b[39;00m\n\u001b[0;32m     15\u001b[0m \u001b[38;5;124;03m\"\"\"Keras models API.\"\"\"\u001b[39;00m\n\u001b[1;32m---> 18\u001b[0m \u001b[38;5;28;01mfrom\u001b[39;00m \u001b[38;5;21;01mkeras\u001b[39;00m\u001b[38;5;21;01m.\u001b[39;00m\u001b[38;5;21;01mengine\u001b[39;00m\u001b[38;5;21;01m.\u001b[39;00m\u001b[38;5;21;01mfunctional\u001b[39;00m \u001b[38;5;28;01mimport\u001b[39;00m Functional\n\u001b[0;32m     19\u001b[0m \u001b[38;5;28;01mfrom\u001b[39;00m \u001b[38;5;21;01mkeras\u001b[39;00m\u001b[38;5;21;01m.\u001b[39;00m\u001b[38;5;21;01mengine\u001b[39;00m\u001b[38;5;21;01m.\u001b[39;00m\u001b[38;5;21;01msequential\u001b[39;00m \u001b[38;5;28;01mimport\u001b[39;00m Sequential\n\u001b[0;32m     20\u001b[0m \u001b[38;5;28;01mfrom\u001b[39;00m \u001b[38;5;21;01mkeras\u001b[39;00m\u001b[38;5;21;01m.\u001b[39;00m\u001b[38;5;21;01mengine\u001b[39;00m\u001b[38;5;21;01m.\u001b[39;00m\u001b[38;5;21;01mtraining\u001b[39;00m \u001b[38;5;28;01mimport\u001b[39;00m Model\n",
      "File \u001b[1;32m~\\anaconda3\\lib\\site-packages\\keras\\engine\\functional.py:24\u001b[0m, in \u001b[0;36m<module>\u001b[1;34m\u001b[0m\n\u001b[0;32m     21\u001b[0m \u001b[38;5;28;01mimport\u001b[39;00m \u001b[38;5;21;01mitertools\u001b[39;00m\n\u001b[0;32m     22\u001b[0m \u001b[38;5;28;01mimport\u001b[39;00m \u001b[38;5;21;01mwarnings\u001b[39;00m\n\u001b[1;32m---> 24\u001b[0m \u001b[38;5;28;01mimport\u001b[39;00m \u001b[38;5;21;01mtensorflow\u001b[39;00m\u001b[38;5;21;01m.\u001b[39;00m\u001b[38;5;21;01mcompat\u001b[39;00m\u001b[38;5;21;01m.\u001b[39;00m\u001b[38;5;21;01mv2\u001b[39;00m \u001b[38;5;28;01mas\u001b[39;00m \u001b[38;5;21;01mtf\u001b[39;00m\n\u001b[0;32m     26\u001b[0m \u001b[38;5;28;01mfrom\u001b[39;00m \u001b[38;5;21;01mkeras\u001b[39;00m \u001b[38;5;28;01mimport\u001b[39;00m backend\n\u001b[0;32m     27\u001b[0m \u001b[38;5;28;01mfrom\u001b[39;00m \u001b[38;5;21;01mkeras\u001b[39;00m\u001b[38;5;21;01m.\u001b[39;00m\u001b[38;5;21;01mdtensor\u001b[39;00m \u001b[38;5;28;01mimport\u001b[39;00m layout_map \u001b[38;5;28;01mas\u001b[39;00m layout_map_lib\n",
      "\u001b[1;31mModuleNotFoundError\u001b[0m: No module named 'tensorflow'"
     ]
    }
   ],
   "source": [
    "from keras.models import Model\n",
    "from keras.layers import Flatten,Dense\n",
    "from keras.applications.vgg16 import VGG16\n",
    "import matplotlib.pyplot as plot\n",
    "from glob import glob"
   ]
  },
  {
   "cell_type": "code",
   "execution_count": null,
   "id": "eab699e9",
   "metadata": {},
   "outputs": [],
   "source": []
  }
 ],
 "metadata": {
  "kernelspec": {
   "display_name": "Python 3 (ipykernel)",
   "language": "python",
   "name": "python3"
  },
  "language_info": {
   "codemirror_mode": {
    "name": "ipython",
    "version": 3
   },
   "file_extension": ".py",
   "mimetype": "text/x-python",
   "name": "python",
   "nbconvert_exporter": "python",
   "pygments_lexer": "ipython3",
   "version": "3.9.12"
  }
 },
 "nbformat": 4,
 "nbformat_minor": 5
}
